Workbook
Name ListaCategorias: 'Catálogo Productos'!$C$3:$C$52
Name ListaProductos: 'Catálogo Productos'!$B$3:$B$200

Sheet 📋 Instrucciones
A1: ÁVILA MUSIC - CÓMO AGREGAR UN NUEVO MES
A3: PASOS PARA CREAR EL REGISTRO DE UN NUEVO MES:
A5: PASO 1: Haz clic derecho en la pestaña 'Febrero 2026 - Ventas'
A6: → Selecciona 'Mover o copiar'
A7: → Marca la casilla 'Crear una copia'
A8: → Renombra la nueva hoja como: 'Abril 2026 - Ventas'
A10: PASO 2: Haz lo mismo con 'PLANTILLA - Resumen'
A11: → Renombra la nueva hoja como: 'Abril 2026 - Resumen'
A13: PASO 3: En la nueva hoja 'Abril 2026 - Resumen',
A14: cambia todas las referencias de 'Febrero 2026 - Ventas'
A15: por 'Abril 2026 - Ventas'
A17: PASO 4: Ve a 'Configuración' y actualiza el Mes y Año activo
... A48: NOTA: Febrero y Marzo 2026 ya tienen sus precios congelados.

Sheet Configuración
A1: ÁVILA MUSIC - CONFIGURACIÓN FINANCIERA
A3: COMISIONES Y COSTOS MERCADOLIBRE
B4: Días del Mes | C4: 31 | D4: Días del mes activo — ajusta si el mes tiene 28, 29 o 30 días
B5: Comisión MercadoLibre (%) | C5: 0.11 | D5: Porcentaje que cobra ML por cada venta
B6: Costo de Envío por Venta (USD) | C6: 1.3 | D6: Configurable — baja si superas 50 ventas/mes
B7: Tasa de referencia (USD) | C7: 457.5 | D7: Referencia interna — no se usa en cálculos USD
B8: Factor de ajuste (%) | C8: 0.34 | D8: No aplica en modelo 100% USD
B9: Lead Time Proveedor (meses) | C9: 4 | D9: Meses desde pedido hasta recibir (producción + envío)
B10: Colchón de Seguridad (meses) | C10: 1 | D10: Meses de colchón de seguridad (recomendado: 1 mes mínimo con 4 meses lead time)
B11: Días Transcurridos del Mes | C11: 10 | D11: Días ya transcurridos del mes activo (actualiza regularmente)
A12: DISTRIBUCIÓN DE GANANCIA NETA
B14: % Reinversión | C14: 0.7 | D14: Para comprar más inventario y hacer crecer el negocio
B15: % Sueldo / Ganancia Personal | C15: 0.3 | D15: Tu compensación — úsalo para ti o para decisiones
B16: Total (%) | C16: =C14+C15 -> 1 | D16: =IF(C16=1,"✓ Correcto","⚠ Debe sumar 100%") -> ✓ Correcto
A18: MES ACTIVO DE REGISTRO
B20: Mes | C20: Abril | D20: Nombre del mes que estás registrando
B21: Año | C21: 2026 | D21: Año actual
A23: LEYENDA
B25: Celdas amarillas + texto azul | D25: Datos que TU modificas (inputs)
B26: Celdas grises + texto negro | D26: Formulas automaticas (NO tocar)

Sheet Abril 2026 - Ventas
A1: ÁVILA MUSIC - REGISTRO DE VENTAS DETALLADO
A2: ='Configuración'!C17&" "&'Configuración'!C18
A3: Al cerrar el mes: selecciona E5:F54 -> Copiar -> Pegado Especial -> Valores (congela precios historicos)
A4: # | B4: Fecha | C4: Producto | D4: Categoría | E4: Costo USD | F4: Precio Venta USD | G4: Comisión ML | H4: Envío Gratis | I4: Comisión ML | J4: Costo Envío USD | K4: Ingreso Neto USD | L4: Ganancia Bruta USD | M4: Margen % | N4: Descuento USD
A5: 1 | B5: 46113 | C5: Cuerdas de Violin 4/4 | D5: =IFERROR(VLOOKUP(C5,'Catálogo Productos'!$B$3:$E$200,2,0),"") -> Violin | E5: =IFERROR(VLOOKUP(C5,'Catálogo Productos'!$B$3:$E$200,3,0),"") -> 1.06 | F5: =IFERROR(VLOOKUP(C5,'Catálogo Productos'!$B$3:$E$200,4,0),"") -> 4.99 | G5: =IF(F5="","",IF(I5="SÍ",F5*'Configuración'!$C$5,0)) -> 0.5489 | H5: SÍ | I5: SÍ | J5: =IF(F5="","",IF(H5="SÍ",'Configuración'!$C$6,0)) -> 1.3 | K5: =IF(F5="","",F5-G5-J5) -> 3.1411 | L5: =IF(F5="","",K5-E5-IF(N5="",0,N5)) -> 2.0811 | M5: =IF(F5="","",IF(K5=0,0,L5/K5)) -> 0.6625386
A6: 2 | B6: 46113 | C6: Cuerdas Alice Clasica A106 | D6: =IFERROR(VLOOKUP(C6,'Catálogo Productos'!$B$3:$E$200,2,0),"") -> Guitarra Clasica | E6: =IFERROR(VLOOKUP(C6,'Catálogo Productos'!$B$3:$E$200,3,0),"") -> 1.21 | F6: =IFERROR(VLOOKUP(C6,'Catálogo Productos'!$B$3:$E$200,4,0),"") -> 5.49 | G6: =IF(F6="","",IF(I6="SÍ",F6*'Configuración'!$C$5,0)) -> 0.6039 | H6: SÍ | I6: SÍ | J6: =IF(F6="","",IF(H6="SÍ",'Configuración'!$C$6,0)) -> 1.3 | K6: =IF(F6="","",F6-G6-J6) -> 3.5861 | L6: =IF(F6="","",K6-E6-IF(N6="",0,N6)) -> 2.3761 | M6: =IF(F6="","",IF(K6=0,0,L6/K6)) -> 0.6625861
A7: 3 | B7: 46113 | C7: Cuerdas Alice Electrica SL | D7: =IFERROR(VLOOKUP(C7,'Catálogo Productos'!$B$3:$E$200,2,0),"") -> Guitarra Electrica | E7: =IFERROR(VLOOKUP(C7,'Catálogo Productos'!$B$3:$E$200,3,0),"") -> 1.21 | F7: =IFERROR(VLOOKUP(C7,'Catálogo Productos'!$B$3:$E$200,4,0),"") -> 5.49 | G7: =IF(F7="","",IF(I7="SÍ",F7*'Configuración'!$C$5,0)) -> 0.6039 | H7: No | I7: SÍ | J7: =IF(F7="","",IF(H7="SÍ",'Configuración'!$C$6,0)) -> 0 | K7: =IF(F7="","",F7-G7-J7) -> 4.8861 | L7: =IF(F7="","",K7-E7-IF(N7="",0,N7)) -> 3.6761 | M7: =IF(F7="","",IF(K7=0,0,L7/K7)) -> 0.75235873
A8: 4 | B8: 46114 | C8: Cable Hebikuo XA03 | D8: =IFERROR(VLOOKUP(C8,'Catálogo Productos'!$B$3:$E$200,2,0),"") -> Cables | E8: =IFERROR(VLOOKUP(C8,'Catálogo Productos'!$B$3:$E$200,3,0),"") -> 1.91 | F8: =IFERROR(VLOOKUP(C8,'Catálogo Productos'!$B$3:$E$200,4,0),"") -> 10 | G8: =IF(F8="","",IF(I8="SÍ",F8*'Configuración'!$C$5,0)) -> 1.1 | H8: SÍ | I8: SÍ | J8: =IF(F8="","",IF(H8="SÍ",'Configuración'!$C$6,0)) -> 1.3 | K8: =IF(F8="","",F8-G8-J8) -> 7.6 | L8: =IF(F8="","",K8-E8-IF(N8="",0,N8)) -> 5.69 | M8: =IF(F8="","",IF(K8=0,0,L8/K8)) -> 0.74868421
A9: 5 | B9: 46114 | C9: Cuerdas Alice Electrica SL | D9: =IFERROR(VLOOKUP(C9,'Catálogo Productos'!$B$3:$E$200,2,0),"") -> Guitarra Electrica | E9: =IFERROR(VLOOKUP(C9,'Catálogo Productos'!$B$3:$E$200,3,0),"") -> 1.21 | F9: =IFERROR(VLOOKUP(C9,'Catálogo Productos'!$B$3:$E$200,4,0),"") -> 5.49 | G9: =IF(F9="","",IF(I9="SÍ",F9*'Configuración'!$C$5,0)) -> 0.6039 | H9: SÍ | I9: SÍ | J9: =IF(F9="","",IF(H9="SÍ",'Configuración'!$C$6,0)) -> 1.3 | K9: =IF(F9="","",F9-G9-J9) -> 3.5861 | L9: =IF(F9="","",K9-E9-IF(N9="",0,N9)) -> 2.3761 | M9: =IF(F9="","",IF(K9=0,0,L9/K9)) -> 0.6625861
A10: 6 | B10: 46114 | C10: Cuerdas Alice Electrica SL | D10: =IFERROR(VLOOKUP(C10,'Catálogo Productos'!$B$3:$E$200,2,0),"") -> Guitarra Electrica | E10: =IFERROR(VLOOKUP(C10,'Catálogo Productos'!$B$3:$E$200,3,0),"") -> 1.21 | F10: =IFERROR(VLOOKUP(C10,'Catálogo Productos'!$B$3:$E$200,4,0),"") -> 5.49 | G10: =IF(F10="","",IF(I10="SÍ",F10*'Configuración'!$C$5,0)) -> 0.6039 | H10: SÍ | I10: SÍ | J10: =IF(F10="","",IF(H10="SÍ",'Configuración'!$C$6,0)) -> 1.3 | K10: =IF(F10="","",F10-G10-J10) -> 3.5861 | L10: =IF(F10="","",K10-E10-IF(N10="",0,N10)) -> 2.3761 | M10: =IF(F10="","",IF(K10=0,0,L10/K10)) -> 0.6625861
A11: 7 | B11: 46114 | C11: Cuerdas Alice Electrica SL | D11: =IFERROR(VLOOKUP(C11,'Catálogo Productos'!$B$3:$E$200,2,0),"") -> Guitarra Electrica | E11: =IFERROR(VLOOKUP(C11,'Catálogo Productos'!$B$3:$E$200,3,0),"") -> 1.21 | F11: =IFERROR(VLOOKUP(C11,'Catálogo Productos'!$B$3:$E$200,4,0),"") -> 5.49 | G11: =IF(F11="","",IF(I11="SÍ",F11*'Configuración'!$C$5,0)) -> 0.6039 | H11: No | I11: SÍ | J11: =IF(F11="","",IF(H11="SÍ",'Configuración'!$C$6,0)) -> 0 | K11: =IF(F11="","",F11-G11-J11) -> 4.8861 | L11: =IF(F11="","",K11-E11-IF(N11="",0,N11)) -> 3.6761 | M11: =IF(F11="","",IF(K11=0,0,L11/K11)) -> 0.75235873
A12: 8 | B12: 46116 | C12: Base pared Guitarra/Bajo | D12: =IFERROR(VLOOKUP(C12,'Catálogo Productos'!$B$3:$E$200,2,0),"") -> Bases, Stand, Atriles | E12: =IFERROR(VLOOKUP(C12,'Catálogo Productos'!$B$3:$E$200,3,0),"") -> 0.5 | F12: =IFERROR(VLOOKUP(C12,'Catálogo Productos'!$B$3:$E$200,4,0),"") -> 4.99 | G12: =IF(F12="","",IF(I12="SÍ",F12*'Configuración'!$C$5,0)) -> 0.5489 | H12: SÍ | I12: SÍ | J12: =IF(F12="","",IF(H12="SÍ",'Configuración'!$C$6,0)) -> 1.3 | K12: =IF(F12="","",F12-G12-J12) -> 3.1411 | L12: =IF(F12="","",K12-E12-IF(N12="",0,N12)) -> 2.6411 | M12: =IF(F12="","",IF(K12=0,0,L12/K12)) -> 0.84082009
A13: 9 | B13: 46116 | C13: Base pared Guitarra/Bajo | D13: =IFERROR(VLOOKUP(C13,'Catálogo Productos'!$B$3:$E$200,2,0),"") -> Bases, Stand, Atriles | E13: =IFERROR(VLOOKUP(C13,'Catálogo Productos'!$B$3:$E$200,3,0),"") -> 0.5 | F13: =IFERROR(VLOOKUP(C13,'Catálogo Productos'!$B$3:$E$200,4,0),"") -> 4.99 | G13: =IF(F13="","",IF(I13="SÍ",F13*'Configuración'!$C$5,0)) -> 0.5489 | H13: SÍ | I13: SÍ | J13: =IF(F13="","",IF(H13="SÍ",'Configuración'!$C$6,0)) -> 1.3 | K13: =IF(F13="","",F13-G13-J13) -> 3.1411 | L13: =IF(F13="","",K13-E13-IF(N13="",0,N13)) -> 2.6411 | M13: =IF(F13="","",IF(K13=0,0,L13/K13)) -> 0.84082009
A14: 10 | B14: 46117 | C14: Base pared Guitarra/Bajo | D14: =IFERROR(VLOOKUP(C14,'Catálogo Productos'!$B$3:$E$200,2,0),"") -> Bases, Stand, Atriles | E14: =IFERROR(VLOOKUP(C14,'Catálogo Productos'!$B$3:$E$200,3,0),"") -> 0.5 | F14: =IFERROR(VLOOKUP(C14,'Catálogo Productos'!$B$3:$E$200,4,0),"") -> 4.99 | G14: =IF(F14="","",IF(I14="SÍ",F14*'Configuración'!$C$5,0)) -> 0.5489 | H14: No | I14: SÍ | J14: =IF(F14="","",IF(H14="SÍ",'Configuración'!$C$6,0)) -> 0 | K14: =IF(F14="","",F14-G14-J14) -> 4.4411 | L14: =IF(F14="","",K14-E14-IF(N14="",0,N14)) -> 3.9411 | M14: =IF(F14="","",IF(K14=0,0,L14/K14)) -> 0.88741528
A15: 11 | B15: 46118 | C15: Capotraste | D15: =IFERROR(VLOOKUP(C15,'Catálogo Productos'!$B$3:$E$200,2,0),"") -> Capostraste | E15: =IFERROR(VLOOKUP(C15,'Catálogo Productos'!$B$3:$E$200,3,0),"") -> 0.65 | F15: =IFERROR(VLOOKUP(C15,'Catálogo Productos'!$B$3:$E$200,4,0),"") -> 6.99 | G15: =IF(F15="","",IF(I15="SÍ",F15*'Configuración'!$C$5,0)) -> 0.7689 | H15: SÍ | I15: SÍ | J15: =IF(F15="","",IF(H15="SÍ",'Configuración'!$C$6,0)) -> 1.3 | K15: =IF(F15="","",F15-G15-J15) -> 4.9211 | L15: =IF(F15="","",K15-E15-IF(N15="",0,N15)) -> 4.2711 | M15: =IF(F15="","",IF(K15=0,0,L15/K15)) -> 0.86791571
A16: 12 | B16: 46118 | C16: Cuerdas Alice Electrica L | D16: =IFERROR(VLOOKUP(C16,'Catálogo Productos'!$B$3:$E$200,2,0),"") -> Guitarra Electrica | E16: =IFERROR(VLOOKUP(C16,'Catálogo Productos'!$B$3:$E$200,3,0),"") -> 1.21 | F16: =IFERROR(VLOOKUP(C16,'Catálogo Productos'!$B$3:$E$200,4,0),"") -> 5.49 | G16: =IF(F16="","",IF(I16="SÍ",F16*'Configuración'!$C$5,0)) -> 0.6039 | H16: SÍ | I16: SÍ | J16: =IF(F16="","",IF(H16="SÍ",'Configuración'!$C$6,0)) -> 1.3 | K16: =IF(F16="","",F16-G16-J16) -> 3.5861 | L16: =IF(F16="","",K16-E16-IF(N16="",0,N16)) -> 2.3761 | M16: =IF(F16="","",IF(K16=0,0,L16/K16)) -> 0.6625861
... A21: 17 | B21: 46119 | C21: Cuerdas Alice Electrica SL | D21: =IFERROR(VLOOKUP(C21,'Catálogo Productos'!$B$3:$E$200,2,0),"") -> Guitarra Electrica | E21: =IFERROR(VLOOKUP(C21,'Catálogo Productos'!$B$3:$E$200,3,0),"") -> 1.21 | F21: =IFERROR(VLOOKUP(C21,'Catálogo Productos'!$B$3:$E$200,4,0),"") -> 5.49 | G21: =IF(F21="","",IF(I21="SÍ",F21*'Configuración'!$C$5,0)) -> 0.6039 | H21: SÍ | I21: SÍ | J21: =IF(F21="","",IF(H21="SÍ",'Configuración'!$C$6,0)) -> 1.3 | K21: =IF(F21="","",F21-G21-J21) -> 3.5861 | L21: =IF(F21="","",K21-E21-IF(N21="",0,N21)) -> 2.3761 | M21: =IF(F21="","",IF(K21=0,0,L21/K21)) -> 0.6625861
A22: 18 | B22: 46119 | C22: Cuerdas Alice Electrica L | D22: =IFERROR(VLOOKUP(C22,'Catálogo Productos'!$B$3:$E$200,2,0),"") -> Guitarra Electrica | E22: =IFERROR(VLOOKUP(C22,'Catálogo Productos'!$B$3:$E$200,3,0),"") -> 1.21 | F22: =IFERROR(VLOOKUP(C22,'Catálogo Productos'!$B$3:$E$200,4,0),"") -> 5.49 | G22: =IF(F22="","",IF(I22="SÍ",F22*'Configuración'!$C$5,0)) -> 0 | H22: No | I22: NO | J22: =IF(F22="","",IF(H22="SÍ",'Configuración'!$C$6,0)) -> 0 | K22: =IF(F22="","",F22-G22-J22) -> 5.49 | L22: =IF(F22="","",K22-E22-IF(N22="",0,N22)) -> 3.78 | M22: =IF(F22="","",IF(K22=0,0,L22/K22)) -> 0.68852459 | N22: 0.5
A23: 19 | B23: 46119 | C23: Cuerdas Alice Electrica L | D23: =IFERROR(VLOOKUP(C23,'Catálogo Productos'!$B$3:$E$200,2,0),"") -> Guitarra Electrica | E23: =IFERROR(VLOOKUP(C23,'Catálogo Productos'!$B$3:$E$200,3,0),"") -> 1.21 | F23: =IFERROR(VLOOKUP(C23,'Catálogo Productos'!$B$3:$E$200,4,0),"") -> 5.49 | G23: =IF(F23="","",IF(I23="SÍ",F23*'Configuración'!$C$5,0)) -> 0 | H23: No | I23: NO | J23: =IF(F23="","",IF(H23="SÍ",'Configuración'!$C$6,0)) -> 0 | K23: =IF(F23="","",F23-G23-J23) -> 5.49 | L23: =IF(F23="","",K23-E23-IF(N23="",0,N23)) -> 3.78 | M23: =IF(F23="","",IF(K23=0,0,L23/K23)) -> 0.68852459 | N23: 0.5
A24: 20 | B24: 46119 | C24: Cuerdas Alice Electrica SL | D24: =IFERROR(VLOOKUP(C24,'Catálogo Productos'!$B$3:$E$200,2,0),"") -> Guitarra Electrica | E24: =IFERROR(VLOOKUP(C24,'Catálogo Productos'!$B$3:$E$200,3,0),"") -> 1.21 | F24: =IFERROR(VLOOKUP(C24,'Catálogo Productos'!$B$3:$E$200,4,0),"") -> 5.49 | G24: =IF(F24="","",IF(I24="SÍ",F24*'Configuración'!$C$5,0)) -> 0.6039 | H24: SÍ | I24: SÍ | J24: =IF(F24="","",IF(H24="SÍ",'Configuración'!$C$6,0)) -> 1.3 | K24: =IF(F24="","",F24-G24-J24) -> 3.5861 | L24: =IF(F24="","",K24-E24-IF(N24="",0,N24)) -> 2.3761 | M24: =IF(F24="","",IF(K24=0,0,L24/K24)) -> 0.6625861
A25: 21 | B25: 46119 | C25: Hombrera Violin 3/4 4/4 | D25: =IFERROR(VLOOKUP(C25,'Catálogo Productos'!$B$3:$E$200,2,0),"") -> Violin | E25: =IFERROR(VLOOKUP(C25,'Catálogo Productos'!$B$3:$E$200,3,0),"") -> 2.69 | F25: =IFERROR(VLOOKUP(C25,'Catálogo Productos'!$B$3:$E$200,4,0),"") -> 11 | G25: =IF(F25="","",IF(I25="SÍ",F25*'Configuración'!$C$5,0)) -> 1.21 | H25: SÍ | I25: SÍ | J25: =IF(F25="","",IF(H25="SÍ",'Configuración'!$C$6,0)) -> 1.3 | K25: =IF(F25="","",F25-G25-J25) -> 8.49 | L25: =IF(F25="","",K25-E25-IF(N25="",0,N25)) -> 4.8 | M25: =IF(F25="","",IF(K25=0,0,L25/K25)) -> 0.56537102 | N25: 1
A26: 22 | B26: 46119 | C26: Cuerdas Alice Clasica A106 | D26: =IFERROR(VLOOKUP(C26,'Catálogo Productos'!$B$3:$E$200,2,0),"") -> Guitarra Clasica | E26: =IFERROR(VLOOKUP(C26,'Catálogo Productos'!$B$3:$E$200,3,0),"") -> 1.21 | F26: =IFERROR(VLOOKUP(C26,'Catálogo Productos'!$B$3:$E$200,4,0),"") -> 5.49 | G26: =IF(F26="","",IF(I26="SÍ",F26*'Configuración'!$C$5,0)) -> 0.6039 | H26: SÍ | I26: SÍ | J26: =IF(F26="","",IF(H26="SÍ",'Configuración'!$C$6,0)) -> 1.3 | K26: =IF(F26="","",F26-G26-J26) -> 3.5861 | L26: =IF(F26="","",K26-E26-IF(N26="",0,N26)) -> 2.3761 | M26: =IF(F26="","",IF(K26=0,0,L26/K26)) -> 0.6625861
A27: 23 | B27: 46119 | C27: Hombrera Violin 3/4 4/4 | D27: =IFERROR(VLOOKUP(C27,'Catálogo Productos'!$B$3:$E$200,2,0),"") -> Violin | E27: =IFERROR(VLOOKUP(C27,'Catálogo Productos'!$B$3:$E$200,3,0),"") -> 2.69 | F27: =IFERROR(VLOOKUP(C27,'Catálogo Productos'!$B$3:$E$200,4,0),"") -> 11 | G27: =IF(F27="","",IF(I27="SÍ",F27*'Configuración'!$C$5,0)) -> 1.21 | H27: SÍ | I27: SÍ | J27: =IF(F27="","",IF(H27="SÍ",'Configuración'!$C$6,0)) -> 1.3 | K27: =IF(F27="","",F27-G27-J27) -> 8.49 | L27: =IF(F27="","",K27-E27-IF(N27="",0,N27)) -> 4.8 | M27: =IF(F27="","",IF(K27=0,0,L27/K27)) -> 0.56537102 | N27: 1
A28: 24 | B28: 46119 | C28: Cuerdas Alice Clasica A106 | D28: =IFERROR(VLOOKUP(C28,'Catálogo Productos'!$B$3:$E$200,2,0),"") -> Guitarra Clasica | E28: =IFERROR(VLOOKUP(C28,'Catálogo Productos'!$B$3:$E$200,3,0),"") -> 1.21 | F28: =IFERROR(VLOOKUP(C28,'Catálogo Productos'!$B$3:$E$200,4,0),"") -> 5.49 | G28: =IF(F28="","",IF(I28="SÍ",F28*'Configuración'!$C$5,0)) -> 0.6039 | H28: No | I28: SÍ | J28: =IF(F28="","",IF(H28="SÍ",'Configuración'!$C$6,0)) -> 0 | K28: =IF(F28="","",F28-G28-J28) -> 4.8861 | L28: =IF(F28="","",K28-E28-IF(N28="",0,N28)) -> 3.6761 | M28: =IF(F28="","",IF(K28=0,0,L28/K28)) -> 0.75235873
A29: 25 | B29: 46119 | C29: Baqueta Bateria 5B | D29: =IFERROR(VLOOKUP(C29,'Catálogo Productos'!$B$3:$E$200,2,0),"") -> Bateria | E29: =IFERROR(VLOOKUP(C29,'Catálogo Productos'!$B$3:$E$200,3,0),"") -> 0.71 | F29: =IFERROR(VLOOKUP(C29,'Catálogo Productos'!$B$3:$E$200,4,0),"") -> 5 | G29: =IF(F29="","",IF(I29="SÍ",F29*'Configuración'!$C$5,0)) -> 0.55 | H29: No | I29: SÍ | J29: =IF(F29="","",IF(H29="SÍ",'Configuración'!$C$6,0)) -> 0 | K29: =IF(F29="","",F29-G29-J29) -> 4.45 | L29: =IF(F29="","",K29-E29-IF(N29="",0,N29)) -> 3.74 | M29: =IF(F29="","",IF(K29=0,0,L29/K29)) -> 0.84044944
A30: 26 | B30: 46119 | C30: Cable Hebikuo XA03 | D30: =IFERROR(VLOOKUP(C30,'Catálogo Productos'!$B$3:$E$200,2,0),"") -> Cables | E30: =IFERROR(VLOOKUP(C30,'Catálogo Productos'!$B$3:$E$200,3,0),"") -> 1.91 | F30: =IFERROR(VLOOKUP(C30,'Catálogo Productos'!$B$3:$E$200,4,0),"") -> 10 | G30: =IF(F30="","",IF(I30="SÍ",F30*'Configuración'!$C$5,0)) -> 1.1 | H30: SÍ | I30: SÍ | J30: =IF(F30="","",IF(H30="SÍ",'Configuración'!$C$6,0)) -> 1.3 | K30: =IF(F30="","",F30-G30-J30) -> 7.6 | L30: =IF(F30="","",K30-E30-IF(N30="",0,N30)) -> 5.69 | M30: =IF(F30="","",IF(K30=0,0,L30/K30)) -> 0.74868421
A31: 27 | B31: 46119 | C31: Cuerdas Bajo 4C Alice | D31: =IFERROR(VLOOKUP(C31,'Catálogo Productos'!$B$3:$E$200,2,0),"") -> Bajo Electrico | E31: =IFERROR(VLOOKUP(C31,'Catálogo Productos'!$B$3:$E$200,3,0),"") -> 3.03 | F31: =IFERROR(VLOOKUP(C31,'Catálogo Productos'!$B$3:$E$200,4,0),"") -> 12.99 | G31: =IF(F31="","",IF(I31="SÍ",F31*'Configuración'!$C$5,0)) -> 1.4289 | H31: SÍ | I31: SÍ | J31: =IF(F31="","",IF(H31="SÍ",'Configuración'!$C$6,0)) -> 1.3 | K31: =IF(F31="","",F31-G31-J31) -> 10.2611 | L31: =IF(F31="","",K31-E31-IF(N31="",0,N31)) -> 7.2311 | M31: =IF(F31="","",IF(K31=0,0,L31/K31)) -> 0.70471002
A32: 28 | B32: 46119 | C32: Cuerdas Alice Clasica A106 | D32: =IFERROR(VLOOKUP(C32,'Catálogo Productos'!$B$3:$E$200,2,0),"") -> Guitarra Clasica | E32: =IFERROR(VLOOKUP(C32,'Catálogo Productos'!$B$3:$E$200,3,0),"") -> 1.21 | F32: =IFERROR(VLOOKUP(C32,'Catálogo Productos'!$B$3:$E$200,4,0),"") -> 5.49 | G32: =IF(F32="","",IF(I32="SÍ",F32*'Configuración'!$C$5,0)) -> 0.6039 | H32: SÍ | I32: SÍ | J32: =IF(F32="","",IF(H32="SÍ",'Configuración'!$C$6,0)) -> 1.3 | K32: =IF(F32="","",F32-G32-J32) -> 3.5861 | L32: =IF(F32="","",K32-E32-IF(N32="",0,N32)) -> 2.3761 | M32: =IF(F32="","",IF(K32=0,0,L32/K32)) -> 0.6625861
A33: 29 | B33: 46120 | C33: Cuerdas Alice Electrica SL | D33: =IFERROR(VLOOKUP(C33,'Catálogo Productos'!$B$3:$E$200,2,0),"") -> Guitarra Electrica | E33: =IFERROR(VLOOKUP(C33,'Catálogo Productos'!$B$3:$E$200,3,0),"") -> 1.21 | F33: =IFERROR(VLOOKUP(C33,'Catálogo Productos'!$B$3:$E$200,4,0),"") -> 5.49 | G33: =IF(F33="","",IF(I33="SÍ",F33*'Configuración'!$C$5,0)) -> 0.6039 | H33: SÍ | I33: SÍ | J33: =IF(F33="","",IF(H33="SÍ",'Configuración'!$C$6,0)) -> 1.3 | K33: =IF(F33="","",F33-G33-J33) -> 3.5861 | L33: =IF(F33="","",K33-E33-IF(N33="",0,N33)) -> 2.3761 | M33: =IF(F33="","",IF(K33=0,0,L33/K33)) -> 0.6625861
A34: 30 | B34: 46120 | C34: Cuerdas Alice Electrica SL | D34: =IFERROR(VLOOKUP(C34,'Catálogo Productos'!$B$3:$E$200,2,0),"") -> Guitarra Electrica | E34: =IFERROR(VLOOKUP(C34,'Catálogo Productos'!$B$3:$E$200,3,0),"") -> 1.21 | F34: =IFERROR(VLOOKUP(C34,'Catálogo Productos'!$B$3:$E$200,4,0),"") -> 5.49 | G34: =IF(F34="","",IF(I34="SÍ",F34*'Configuración'!$C$5,0)) -> 0 | H34: No | I34: NO | J34: =IF(F34="","",IF(H34="SÍ",'Configuración'!$C$6,0)) -> 0 | K34: =IF(F34="","",F34-G34-J34) -> 5.49 | L34: =IF(F34="","",K34-E34-IF(N34="",0,N34)) -> 4.28 | M34: =IF(F34="","",IF(K34=0,0,L34/K34)) -> 0.77959927
A35: 31 | B35: 46120 | C35: Cuerdas Alice Electrica L | D35: =IFERROR(VLOOKUP(C35,'Catálogo Productos'!$B$3:$E$200,2,0),"") -> Guitarra Electrica | E35: =IFERROR(VLOOKUP(C35,'Catálogo Productos'!$B$3:$E$200,3,0),"") -> 1.21 | F35: =IFERROR(VLOOKUP(C35,'Catálogo Productos'!$B$3:$E$200,4,0),"") -> 5.49 | G35: =IF(F35="","",IF(I35="SÍ",F35*'Configuración'!$C$5,0)) -> 0.6039 | H35: SÍ | I35: SÍ | J35: =IF(F35="","",IF(H35="SÍ",'Configuración'!$C$6,0)) -> 1.3 | K35: =IF(F35="","",F35-G35-J35) -> 3.5861 | L35: =IF(F35="","",K35-E35-IF(N35="",0,N35)) -> 2.3761 | M35: =IF(F35="","",IF(K35=0,0,L35/K35)) -> 0.6625861
A36: 32 | B36: 46120 | C36: Cuerdas Bajo 4C Alice | D36: =IFERROR(VLOOKUP(C36,'Catálogo Productos'!$B$3:$E$200,2,0),"") -> Bajo Electrico | E36: =IFERROR(VLOOKUP(C36,'Catálogo Productos'!$B$3:$E$200,3,0),"") -> 3.03 | F36: =IFERROR(VLOOKUP(C36,'Catálogo Productos'!$B$3:$E$200,4,0),"") -> 12.99 | G36: =IF(F36="","",IF(I36="SÍ",F36*'Configuración'!$C$5,0)) -> 0 | H36: No | I36: NO | J36: =IF(F36="","",IF(H36="SÍ",'Configuración'!$C$6,0)) -> 0 | K36: =IF(F36="","",F36-G36-J36) -> 12.99 | L36: =IF(F36="","",K36-E36-IF(N36="",0,N36)) -> 9.96 | M36: =IF(F36="","",IF(K36=0,0,L36/K36)) -> 0.76674365
A37: 33 | B37: 46120 | C37: Cuerdas Bajo 4C Alice | D37: =IFERROR(VLOOKUP(C37,'Catálogo Productos'!$B$3:$E$200,2,0),"") -> Bajo Electrico | E37: =IFERROR(VLOOKUP(C37,'Catálogo Productos'!$B$3:$E$200,3,0),"") -> 3.03 | F37: =IFERROR(VLOOKUP(C37,'Catálogo Productos'!$B$3:$E$200,4,0),"") -> 12.99 | G37: =IF(F37="","",IF(I37="SÍ",F37*'Configuración'!$C$5,0)) -> 0 | H37: No | I37: NO | J37: =IF(F37="","",IF(H37="SÍ",'Configuración'!$C$6,0)) -> 0 | K37: =IF(F37="","",F37-G37-J37) -> 12.99 | L37: =IF(F37="","",K37-E37-IF(N37="",0,N37)) -> 9.96 | M37: =IF(F37="","",IF(K37=0,0,L37/K37)) -> 0.76674365
A38: 34 | B38: 46120 | C38: Pines de Correa | D38: =IFERROR(VLOOKUP(C38,'Catálogo Productos'!$B$3:$E$200,2,0),"") -> Guitarra Acustica | E38: =IFERROR(VLOOKUP(C38,'Catálogo Productos'!$B$3:$E$200,3,0),"") -> 0.01 | F38: =IFERROR(VLOOKUP(C38,'Catálogo Productos'!$B$3:$E$200,4,0),"") -> 5 | G38: =IF(F38="","",IF(I38="SÍ",F38*'Configuración'!$C$5,0)) -> 0.55 | H38: SÍ | I38: SÍ | J38: =IF(F38="","",IF(H38="SÍ",'Configuración'!$C$6,0)) -> 1.3 | K38: =IF(F38="","",F38-G38-J38) -> 3.15 | L38: =IF(F38="","",K38-E38-IF(N38="",0,N38)) -> 3.14 | M38: =IF(F38="","",IF(K38=0,0,L38/K38)) -> 0.9968254
A39: 35 | B39: 46120 | C39: Cuerdas Alice Clasica A106 | D39: =IFERROR(VLOOKUP(C39,'Catálogo Productos'!$B$3:$E$200,2,0),"") -> Guitarra Clasica | E39: =IFERROR(VLOOKUP(C39,'Catálogo Productos'!$B$3:$E$200,3,0),"") -> 1.21 | F39: =IFERROR(VLOOKUP(C39,'Catálogo Productos'!$B$3:$E$200,4,0),"") -> 5.49 | G39: =IF(F39="","",IF(I39="SÍ",F39*'Configuración'!$C$5,0)) -> 0.6039 | H39: SÍ | I39: SÍ | J39: =IF(F39="","",IF(H39="SÍ",'Configuración'!$C$6,0)) -> 1.3 | K39: =IF(F39="","",F39-G39-J39) -> 3.5861 | L39: =IF(F39="","",K39-E39-IF(N39="",0,N39)) -> 2.3761 | M39: =IF(F39="","",IF(K39=0,0,L39/K39)) -> 0.6625861
... A41: 37 | B41: 46120 | C41: Cuerdas Alice Clasica A106 | D41: =IFERROR(VLOOKUP(C41,'Catálogo Productos'!$B$3:$E$200,2,0),"") -> Guitarra Clasica | E41: =IFERROR(VLOOKUP(C41,'Catálogo Productos'!$B$3:$E$200,3,0),"") -> 1.21 | F41: =IFERROR(VLOOKUP(C41,'Catálogo Productos'!$B$3:$E$200,4,0),"") -> 5.49 | G41: =IF(F41="","",IF(I41="SÍ",F41*'Configuración'!$C$5,0)) -> 0.6039 | H41: SÍ | I41: SÍ | J41: =IF(F41="","",IF(H41="SÍ",'Configuración'!$C$6,0)) -> 1.3 | K41: =IF(F41="","",F41-G41-J41) -> 3.5861 | L41: =IF(F41="","",K41-E41-IF(N41="",0,N41)) -> 2.3761 | M41: =IF(F41="","",IF(K41=0,0,L41/K41)) -> 0.6625861
A42: 38 | B42: 46120 | C42: Hombrera Violin 3/4 4/4 | D42: =IFERROR(VLOOKUP(C42,'Catálogo Productos'!$B$3:$E$200,2,0),"") -> Violin | E42: =IFERROR(VLOOKUP(C42,'Catálogo Productos'!$B$3:$E$200,3,0),"") -> 2.69 | F42: =IFERROR(VLOOKUP(C42,'Catálogo Productos'!$B$3:$E$200,4,0),"") -> 11 | G42: =IF(F42="","",IF(I42="SÍ",F42*'Configuración'!$C$5,0)) -> 1.21 | H42: SÍ | I42: SÍ | J42: =IF(F42="","",IF(H42="SÍ",'Configuración'!$C$6,0)) -> 1.3 | K42: =IF(F42="","",F42-G42-J42) -> 8.49 | L42: =IF(F42="","",K42-E42-IF(N42="",0,N42)) -> 4.8 | M42: =IF(F42="","",IF(K42=0,0,L42/K42)) -> 0.56537102 | N42: 1
A43: 39 | B43: 46121 | C43: Cuerdas Alice Electrica SL | D43: =IFERROR(VLOOKUP(C43,'Catálogo Productos'!$B$3:$E$200,2,0),"") -> Guitarra Electrica | E43: =IFERROR(VLOOKUP(C43,'Catálogo Productos'!$B$3:$E$200,3,0),"") -> 1.21 | F43: =IFERROR(VLOOKUP(C43,'Catálogo Productos'!$B$3:$E$200,4,0),"") -> 5.49 | G43: =IF(F43="","",IF(I43="SÍ",F43*'Configuración'!$C$5,0)) -> 0.6039 | H43: SÍ | I43: SÍ | J43: =IF(F43="","",IF(H43="SÍ",'Configuración'!$C$6,0)) -> 1.3 | K43: =IF(F43="","",F43-G43-J43) -> 3.5861 | L43: =IF(F43="","",K43-E43-IF(N43="",0,N43)) -> 2.3761 | M43: =IF(F43="","",IF(K43=0,0,L43/K43)) -> 0.6625861
A44: 40 | B44: 46121 | C44: Cuerdas Alice Electrica SL | D44: =IFERROR(VLOOKUP(C44,'Catálogo Productos'!$B$3:$E$200,2,0),"") -> Guitarra Electrica | E44: =IFERROR(VLOOKUP(C44,'Catálogo Productos'!$B$3:$E$200,3,0),"") -> 1.21 | F44: =IFERROR(VLOOKUP(C44,'Catálogo Productos'!$B$3:$E$200,4,0),"") -> 5.49 | G44: =IF(F44="","",IF(I44="SÍ",F44*'Configuración'!$C$5,0)) -> 0.6039 | H44: SÍ | I44: SÍ | J44: =IF(F44="","",IF(H44="SÍ",'Configuración'!$C$6,0)) -> 1.3 | K44: =IF(F44="","",F44-G44-J44) -> 3.5861 | L44: =IF(F44="","",K44-E44-IF(N44="",0,N44)) -> 2.3761 | M44: =IF(F44="","",IF(K44=0,0,L44/K44)) -> 0.6625861
A45: 41 | B45: 46121 | C45: Cuerdas Alice Folk 11-52 | D45: =IFERROR(VLOOKUP(C45,'Catálogo Productos'!$B$3:$E$200,2,0),"") -> Guitarra Acustica | E45: =IFERROR(VLOOKUP(C45,'Catálogo Productos'!$B$3:$E$200,3,0),"") -> 1.21 | F45: =IFERROR(VLOOKUP(C45,'Catálogo Productos'!$B$3:$E$200,4,0),"") -> 5.49 | G45: =IF(F45="","",IF(I45="SÍ",F45*'Configuración'!$C$5,0)) -> 0.6039 | H45: SÍ | I45: SÍ | J45: =IF(F45="","",IF(H45="SÍ",'Configuración'!$C$6,0)) -> 1.3 | K45: =IF(F45="","",F45-G45-J45) -> 3.5861 | L45: =IF(F45="","",K45-E45-IF(N45="",0,N45)) -> 2.3761 | M45: =IF(F45="","",IF(K45=0,0,L45/K45)) -> 0.6625861
...

Sheet Abril 2026 - Resumen
A1: Cuerdas Bajo 4C Alice
A2: ='Configuración'!C20&" "&'Configuración'!C21 -> Abril 2026
A4: RESUMEN DE INGRESOS
B6: Ventas Totales (USD) | C6: ='Abril 2026 - Ventas'!F158 -> 1120.87
B7: (-) Comisiones MercadoLibre | C7: ='Abril 2026 - Ventas'!G158 -> 101.3738
B8: (-) Costos de Envío | C8: ='Abril 2026 - Ventas'!J158 -> 136.5
B9: Ingreso Neto (lo que recibes) | C9: ='Abril 2026 - Ventas'!K158 -> 882.9962
B10: (-) Costo Total de Mercancía | C10: ='Abril 2026 - Ventas'!E158 -> 206.65
B11: GANANCIA BRUTA | C11: ='Abril 2026 - Ventas'!L158 -> 666.3462
A13: ANÁLISIS DE GANANCIA
B15: Ingreso Neto (USD) | C15: =C9 -> 882.9962 | E15: Lo que recibes después de comisiones y envíos
B16: Ganancia Bruta (USD) | C16: =C11 -> 666.3462 | E16: Ventas netas menos costo de mercancía
B17: (-) Costo de Mercancía (USD) | C17: =C10 -> 206.65
B18: GANANCIA NETA (USD) | C18: =C15-C10 -> 676.3462
A21: DISTRIBUCIÓN DE GANANCIA REAL
B23: Ganancia Neta del Mes | C23: =C18 -> 676.3462
B24: → Para Reinversión | C24: =IF(C23>0,C23*'Configuración'!$C$14,0) -> 473.44234 | D24: ='Configuración'!$C$14 -> 0.7 | E24: Para comprar más inventario
B25: → Tu Sueldo / Ganancia Personal | C25: =IF(C23>0,C23*'Configuración'!$C$15,0) -> 202.90386 | D25: ='Configuración'!$C$15 -> 0.3 | E25: Disponible para ti o para decisiones
A27: INDICADORES CLAVE (KPIs)
B29: Total de ventas del mes | C29: ='Abril 2026 - Ventas'!C160 -> 155 | E29: Cantidad de transacciones
B30: Ticket promedio (USD) | C30: =IF(C29>0,C6/C29,0) -> 7.2314194 | E30: Venta promedio por transacción
B31: Ganancia neta promedio por venta | C31: =IF(C29>0,C18/C29,0) -> 4.3635239 | E31: Cuánto ganas en promedio por venta
B32: Margen neto real (%) | C32: =IF(C9=0,0,C18/C9) -> 0.76596728 | E32: % ganancia real sobre ingreso neto
B33: Total pagado a ML (comisiones + envíos) | C33: ='Abril 2026 - Ventas'!G158+'Febrero 2026 - Ventas'!J55 -> #REF! | E33: Lo que le pagas a MercadoLibre
B34: ROI del mes (%) | C34: =IF(C10=0,0,C18/C10) -> 3.2729068 | E34: Retorno sobre inversión en inventario
A36: SEMÁFORO DE SALUD DEL NEGOCIO
B38: ¿Recuperaste la inversión? | C38: =IF(C29=0,"—",IF(C18>0,"✅ SÍ","❌ NO")) -> ✅ SÍ | E38: Ganancia real positiva
B39: ¿El negocio se autosostiene? | C39: =IF(C29=0,"—",IF(C24>0,"✅ SÍ","❌ NO")) -> ✅ SÍ | E39: Hay fondos para reinversión
B40: ¿Genera sueldo para ti? | C40: =IF(C29=0,"—",IF(C25>0,"✅ SÍ","❌ NO")) -> ✅ SÍ | E40: Hay ganancia personal disponible
B41: ¿Superaste 50 ventas? | C41: =IF(C29>=50,"✅ SÍ — ¡Baja tu tarifa de envío!","❌ NO — Aún no") -> ✅ SÍ — ¡Baja tu tarifa de envío! | E41: Meta para reducir costo de envío

Sheet Marzo 2026 - Ventas
A1: ÁVILA MUSIC - REGISTRO DE VENTAS DETALLADO
A2: ='Configuración'!C17&" "&'Configuración'!C18
A4: # | B4: Fecha | C4: Producto | D4: Categoría | E4: Costo USD | F4: Precio Venta USD | G4: Comisión ML | H4: Envío Gratis | I4: Comisión ML | J4: Costo Envío USD | K4: Ingreso Neto USD | L4: Ganancia Bruta USD | M4: Margen % | N4: Descuento USD
A5: 1 | B5: 46104 | C5: Base pared Guitarra/Bajo | D5: =IFERROR(VLOOKUP(C5,'Catálogo Productos'!$B$3:$E$53,2,0),"") -> Bases, Stand, Atriles | E5: =IFERROR(VLOOKUP(C5,'Catálogo Productos'!$B$3:$E$53,3,0),"") -> 0.5 | F5: =IFERROR(VLOOKUP(C5,'Catálogo Productos'!$B$3:$E$53,4,0),"") -> 4.99 | G5: =IF(F5="","",IF(I5="SÍ",F5*'Configuración'!$C$5,0)) -> 0.5489 | H5: SÍ | I5: SÍ | J5: =IF(F5="","",IF(H5="SÍ",'Configuración'!$C$6,0)) -> 1.3 | K5: =IF(F5="","",F5-G5-J5) -> 3.1411 | L5: =IF(F5="","",K5-E5-IF(N5="",0,N5)) -> 2.6411 | M5: =IF(F5="","",IF(K5=0,0,L5/K5)) -> 0.84082009
A6: 2 | B6: 46104 | C6: Capotraste | D6: =IFERROR(VLOOKUP(C6,'Catálogo Productos'!$B$3:$E$53,2,0),"") -> Capostraste | E6: =IFERROR(VLOOKUP(C6,'Catálogo Productos'!$B$3:$E$53,3,0),"") -> 0.65 | F6: =IFERROR(VLOOKUP(C6,'Catálogo Productos'!$B$3:$E$53,4,0),"") -> 6.99 | G6: =IF(F6="","",IF(I6="SÍ",F6*'Configuración'!$C$5,0)) -> 0.7689 | H6: SÍ | I6: SÍ | J6: =IF(F6="","",IF(H6="SÍ",'Configuración'!$C$6,0)) -> 1.3 | K6: =IF(F6="","",F6-G6-J6) -> 4.9211 | L6: =IF(F6="","",K6-E6-IF(N6="",0,N6)) -> 4.2711 | M6: =IF(F6="","",IF(K6=0,0,L6/K6)) -> 0.86791571
A7: 3 | B7: 46104 | C7: Correa Guitarra/Bajo | D7: =IFERROR(VLOOKUP(C7,'Catálogo Productos'!$B$3:$E$53,2,0),"") -> Correas | E7: =IFERROR(VLOOKUP(C7,'Catálogo Productos'!$B$3:$E$53,3,0),"") -> 0.2 | F7: =IFERROR(VLOOKUP(C7,'Catálogo Productos'!$B$3:$E$53,4,0),"") -> 5.49 | G7: =IF(F7="","",IF(I7="SÍ",F7*'Configuración'!$C$5,0)) -> 0.6039 | H7: SÍ | I7: SÍ | J7: =IF(F7="","",IF(H7="SÍ",'Configuración'!$C$6,0)) -> 1.3 | K7: =IF(F7="","",F7-G7-J7) -> 3.5861 | L7: =IF(F7="","",K7-E7-IF(N7="",0,N7)) -> 3.3861 | M7: =IF(F7="","",IF(K7=0,0,L7/K7)) -> 0.94422911
A8: 4 | B8: 46104 | C8: Correa Guitarra/Bajo | D8: =IFERROR(VLOOKUP(C8,'Catálogo Productos'!$B$3:$E$53,2,0),"") -> Correas | E8: =IFERROR(VLOOKUP(C8,'Catálogo Productos'!$B$3:$E$53,3,0),"") -> 0.2 | F8: =IFERROR(VLOOKUP(C8,'Catálogo Productos'!$B$3:$E$53,4,0),"") -> 5.49 | G8: =IF(F8="","",IF(I8="SÍ",F8*'Configuración'!$C$5,0)) -> 0.6039 | H8: SÍ | I8: SÍ | J8: =IF(F8="","",IF(H8="SÍ",'Configuración'!$C$6,0)) -> 1.3 | K8: =IF(F8="","",F8-G8-J8) -> 3.5861 | L8: =IF(F8="","",K8-E8-IF(N8="",0,N8)) -> 3.3861 | M8: =IF(F8="","",IF(K8=0,0,L8/K8)) -> 0.94422911
A9: 5 | B9: 46104 | C9: Cuerdas de Violin 4/4 | D9: =IFERROR(VLOOKUP(C9,'Catálogo Productos'!$B$3:$E$53,2,0),"") -> Violin | E9: =IFERROR(VLOOKUP(C9,'Catálogo Productos'!$B$3:$E$53,3,0),"") -> 1.06 | F9: =IFERROR(VLOOKUP(C9,'Catálogo Productos'!$B$3:$E$53,4,0),"") -> 4.99 | G9: =IF(F9="","",IF(I9="SÍ",F9*'Configuración'!$C$5,0)) -> 0.5489 | H9: SÍ | I9: SÍ | J9: =IF(F9="","",IF(H9="SÍ",'Configuración'!$C$6,0)) -> 1.3 | K9: =IF(F9="","",F9-G9-J9) -> 3.1411 | L9: =IF(F9="","",K9-E9-IF(N9="",0,N9)) -> 2.0811 | M9: =IF(F9="","",IF(K9=0,0,L9/K9)) -> 0.6625386
A10: 6 | B10: 46104 | C10: Cable Hebikuo XA03 | D10: =IFERROR(VLOOKUP(C10,'Catálogo Productos'!$B$3:$E$53,2,0),"") -> Cables | E10: =IFERROR(VLOOKUP(C10,'Catálogo Productos'!$B$3:$E$53,3,0),"") -> 1.91 | F10: =IFERROR(VLOOKUP(C10,'Catálogo Productos'!$B$3:$E$53,4,0),"") -> 10 | G10: =IF(F10="","",IF(I10="SÍ",F10*'Configuración'!$C$5,0)) -> 1.1 | H10: SÍ | I10: SÍ | J10: =IF(F10="","",IF(H10="SÍ",'Configuración'!$C$6,0)) -> 1.3 | K10: =IF(F10="","",F10-G10-J10) -> 7.6 | L10: =IF(F10="","",K10-E10-IF(N10="",0,N10)) -> 5.69 | M10: =IF(F10="","",IF(K10=0,0,L10/K10)) -> 0.74868421
A11: 7 | B11: 24/03/0206 | C11: Cuerdas Alice Clasica A106 | D11: =IFERROR(VLOOKUP(C11,'Catálogo Productos'!$B$3:$E$53,2,0),"") -> Guitarra Clasica | E11: =IFERROR(VLOOKUP(C11,'Catálogo Productos'!$B$3:$E$53,3,0),"") -> 1.21 | F11: =IFERROR(VLOOKUP(C11,'Catálogo Productos'!$B$3:$E$53,4,0),"") -> 5.49 | G11: =IF(F11="","",IF(I11="SÍ",F11*'Configuración'!$C$5,0)) -> 0.6039 | H11: SÍ | I11: SÍ | J11: =IF(F11="","",IF(H11="SÍ",'Configuración'!$C$6,0)) -> 1.3 | K11: =IF(F11="","",F11-G11-J11) -> 3.5861 | L11: =IF(F11="","",K11-E11-IF(N11="",0,N11)) -> 2.3761 | M11: =IF(F11="","",IF(K11=0,0,L11/K11)) -> 0.6625861
A12: 8 | B12: 02/03/0206 | C12: Correa Guitarra/Bajo | D12: =IFERROR(VLOOKUP(C12,'Catálogo Productos'!$B$3:$E$53,2,0),"") -> Correas | E12: =IFERROR(VLOOKUP(C12,'Catálogo Productos'!$B$3:$E$53,3,0),"") -> 0.2 | F12: =IFERROR(VLOOKUP(C12,'Catálogo Productos'!$B$3:$E$53,4,0),"") -> 5.49 | G12: =IF(F12="","",IF(I12="SÍ",F12*'Configuración'!$C$5,0)) -> 0.6039 | H12: SÍ | I12: SÍ | J12: =IF(F12="","",IF(H12="SÍ",'Configuración'!$C$6,0)) -> 1.3 | K12: =IF(F12="","",F12-G12-J12) -> 3.5861 | L12: =IF(F12="","",K12-E12-IF(N12="",0,N12)) -> 3.3861 | M12: =IF(F12="","",IF(K12=0,0,L12/K12)) -> 0.94422911
A13: 9 | B13: 02/03/0206 | C13: Cable Hebikuo XA03 | D13: =IFERROR(VLOOKUP(C13,'Catálogo Productos'!$B$3:$E$53,2,0),"") -> Cables | E13: =IFERROR(VLOOKUP(C13,'Catálogo Productos'!$B$3:$E$53,3,0),"") -> 1.91 | F13: =IFERROR(VLOOKUP(C13,'Catálogo Productos'!$B$3:$E$53,4,0),"") -> 10 | G13: =IF(F13="","",IF(I13="SÍ",F13*'Configuración'!$C$5,0)) -> 1.1 | H13: SÍ | I13: SÍ | J13: =IF(F13="","",IF(H13="SÍ",'Configuración'!$C$6,0)) -> 1.3 | K13: =IF(F13="","",F13-G13-J13) -> 7.6 | L13: =IF(F13="","",K13-E13-IF(N13="",0,N13)) -> 5.69 | M13: =IF(F13="","",IF(K13=0,0,L13/K13)) -> 0.74868421
A14: 10 | B14: 02/03/0206 | C14: Cable Hebikuo XA03 | D14: =IFERROR(VLOOKUP(C14,'Catálogo Productos'!$B$3:$E$53,2,0),"") -> Cables | E14: =IFERROR(VLOOKUP(C14,'Catálogo Productos'!$B$3:$E$53,3,0),"") -> 1.91 | F14: =IFERROR(VLOOKUP(C14,'Catálogo Productos'!$B$3:$E$53,4,0),"") -> 10 | G14: =IF(F14="","",IF(I14="SÍ",F14*'Configuración'!$C$5,0)) -> 1.1 | H14: SÍ | I14: SÍ | J14: =IF(F14="","",IF(H14="SÍ",'Configuración'!$C$6,0)) -> 1.3 | K14: =IF(F14="","",F14-G14-J14) -> 7.6 | L14: =IF(F14="","",K14-E14-IF(N14="",0,N14)) -> 5.69 | M14: =IF(F14="","",IF(K14=0,0,L14/K14)) -> 0.74868421
A15: 11 | B15: 02/03/0206 | C15: Cuerdas Alice Clasica A106 | D15: =IFERROR(VLOOKUP(C15,'Catálogo Productos'!$B$3:$E$53,2,0),"") -> Guitarra Clasica | E15: =IFERROR(VLOOKUP(C15,'Catálogo Productos'!$B$3:$E$53,3,0),"") -> 1.21 | F15: =IFERROR(VLOOKUP(C15,'Catálogo Productos'!$B$3:$E$53,4,0),"") -> 5.49 | G15: =IF(F15="","",IF(I15="SÍ",F15*'Configuración'!$C$5,0)) -> 0.6039 | H15: SÍ | I15: SÍ | J15: =IF(F15="","",IF(H15="SÍ",'Configuración'!$C$6,0)) -> 1.3 | K15: =IF(F15="","",F15-G15-J15) -> 3.5861 | L15: =IF(F15="","",K15-E15-IF(N15="",0,N15)) -> 2.3761 | M15: =IF(F15="","",IF(K15=0,0,L15/K15)) -> 0.6625861
A16: 12 | B16: 02/03/0206 | C16: Cuerdas de Violin 4/4 | D16: =IFERROR(VLOOKUP(C16,'Catálogo Productos'!$B$3:$E$53,2,0),"") -> Violin | E16: =IFERROR(VLOOKUP(C16,'Catálogo Productos'!$B$3:$E$53,3,0),"") -> 1.06 | F16: =IFERROR(VLOOKUP(C16,'Catálogo Productos'!$B$3:$E$53,4,0),"") -> 4.99 | G16: =IF(F16="","",IF(I16="SÍ",F16*'Configuración'!$C$5,0)) -> 0.5489 | H16: SÍ | I16: SÍ | J16: =IF(F16="","",IF(H16="SÍ",'Configuración'!$C$6,0)) -> 1.3 | K16: =IF(F16="","",F16-G16-J16) -> 3.1411 | L16: =IF(F16="","",K16-E16-IF(N16="",0,N16)) -> 2.0811 | M16: =IF(F16="","",IF(K16=0,0,L16/K16)) -> 0.6625386
A17: 13 | B17: 02/03/0206 | C17: Hombrera Violin 3/4 4/4 | D17: =IFERROR(VLOOKUP(C17,'Catálogo Productos'!$B$3:$E$53,2,0),"") -> Violin | E17: =IFERROR(VLOOKUP(C17,'Catálogo Productos'!$B$3:$E$53,3,0),"") -> 2.69 | F17: =IFERROR(VLOOKUP(C17,'Catálogo Productos'!$B$3:$E$53,4,0),"") -> 11 | G17: =IF(F17="","",IF(I17="SÍ",F17*'Configuración'!$C$5,0)) -> 1.21 | H17: SÍ | I17: SÍ | J17: =IF(F17="","",IF(H17="SÍ",'Configuración'!$C$6,0)) -> 1.3 | K17: =IF(F17="","",F17-G17-J17) -> 8.49 | L17: =IF(F17="","",K17-E17-IF(N17="",0,N17)) -> 5.8 | M17: =IF(F17="","",IF(K17=0,0,L17/K17)) -> 0.68315665
A18: 14 | B18: 02/03/0206 | C18: Cable Hebikuo XA03 | D18: =IFERROR(VLOOKUP(C18,'Catálogo Productos'!$B$3:$E$53,2,0),"") -> Cables | E18: =IFERROR(VLOOKUP(C18,'Catálogo Productos'!$B$3:$E$53,3,0),"") -> 1.91 | F18: =IFERROR(VLOOKUP(C18,'Catálogo Productos'!$B$3:$E$53,4,0),"") -> 10 | G18: =IF(F18="","",IF(I18="SÍ",F18*'Configuración'!$C$5,0)) -> 1.1 | H18: SÍ | I18: SÍ | J18: =IF(F18="","",IF(H18="SÍ",'Configuración'!$C$6,0)) -> 1.3 | K18: =IF(F18="","",F18-G18-J18) -> 7.6 | L18: =IF(F18="","",K18-E18-IF(N18="",0,N18)) -> 5.69 | M18: =IF(F18="","",IF(K18=0,0,L18/K18)) -> 0.74868421
A19: 15 | B19: 02/03/0206 | C19: Cable Hebikuo XA03 | D19: =IFERROR(VLOOKUP(C19,'Catálogo Productos'!$B$3:$E$53,2,0),"") -> Cables | E19: =IFERROR(VLOOKUP(C19,'Catálogo Productos'!$B$3:$E$53,3,0),"") -> 1.91 | F19: =IFERROR(VLOOKUP(C19,'Catálogo Productos'!$B$3:$E$53,4,0),"") -> 10 | G19: =IF(F19="","",IF(I19="SÍ",F19*'Configuración'!$C$5,0)) -> 1.1 | H19: SÍ | I19: SÍ | J19: =IF(F19="","",IF(H19="SÍ",'Configuración'!$C$6,0)) -> 1.3 | K19: =IF(F19="","",F19-G19-J19) -> 7.6 | L19: =IF(F19="","",K19-E19-IF(N19="",0,N19)) -> 5.69 | M19: =IF(F19="","",IF(K19=0,0,L19/K19)) -> 0.74868421
A20: 16 | B20: 02/03/0206 | C20: Cable Hebikuo XA03 | D20: =IFERROR(VLOOKUP(C20,'Catálogo Productos'!$B$3:$E$53,2,0),"") -> Cables | E20: =IFERROR(VLOOKUP(C20,'Catálogo Productos'!$B$3:$E$53,3,0),"") -> 1.91 | F20: =IFERROR(VLOOKUP(C20,'Catálogo Productos'!$B$3:$E$53,4,0),"") -> 10 | G20: =IF(F20="","",IF(I20="SÍ",F20*'Configuración'!$C$5,0)) -> 1.1 | H20: SÍ | I20: SÍ | J20: =IF(F20="","",IF(H20="SÍ",'Configuración'!$C$6,0)) -> 1.3 | K20: =IF(F20="","",F20-G20-J20) -> 7.6 | L20: =IF(F20="","",K20-E20-IF(N20="",0,N20)) -> 5.69 | M20: =IF(F20="","",IF(K20=0,0,L20/K20)) -> 0.74868421
A21: 17 | B21: 02/03/0206 | C21: Cuerdas Alice Electrica SL | D21: =IFERROR(VLOOKUP(C21,'Catálogo Productos'!$B$3:$E$53,2,0),"") -> Guitarra Electrica | E21: =IFERROR(VLOOKUP(C21,'Catálogo Productos'!$B$3:$E$53,3,0),"") -> 1.21 | F21: =IFERROR(VLOOKUP(C21,'Catálogo Productos'!$B$3:$E$53,4,0),"") -> 5.49 | G21: =IF(F21="","",IF(I21="SÍ",F21*'Configuración'!$C$5,0)) -> 0.6039 | H21: SÍ | I21: SÍ | J21: =IF(F21="","",IF(H21="SÍ",'Configuración'!$C$6,0)) -> 1.3 | K21: =IF(F21="","",F21-G21-J21) -> 3.5861 | L21: =IF(F21="","",K21-E21-IF(N21="",0,N21)) -> 2.3761 | M21: =IF(F21="","",IF(K21=0,0,L21/K21)) -> 0.6625861
A22: 18 | B22: 02/03/0206 | C22: Cuerdas Alice Electrica L | D22: =IFERROR(VLOOKUP(C22,'Catálogo Productos'!$B$3:$E$53,2,0),"") -> Guitarra Electrica | E22: =IFERROR(VLOOKUP(C22,'Catálogo Productos'!$B$3:$E$53,3,0),"") -> 1.21 | F22: =IFERROR(VLOOKUP(C22,'Catálogo Productos'!$B$3:$E$53,4,0),"") -> 5.49 | G22: =IF(F22="","",IF(I22="SÍ",F22*'Configuración'!$C$5,0)) -> 0.6039 | H22: SÍ | I22: SÍ | J22: =IF(F22="","",IF(H22="SÍ",'Configuración'!$C$6,0)) -> 1.3 | K22: =IF(F22="","",F22-G22-J22) -> 3.5861 | L22: =IF(F22="","",K22-E22-IF(N22="",0,N22)) -> 2.3761 | M22: =IF(F22="","",IF(K22=0,0,L22/K22)) -> 0.6625861
... A43: 39 | B43: 02/03/0206 | C43: Pines de Correa | D43: =IFERROR(VLOOKUP(C43,'Catálogo Productos'!$B$3:$E$53,2,0),"") -> Guitarra Acustica | E43: =IFERROR(VLOOKUP(C43,'Catálogo Productos'!$B$3:$E$53,3,0),"") -> 0.01 | F43: =IFERROR(VLOOKUP(C43,'Catálogo Productos'!$B$3:$E$53,4,0),"") -> 5 | G43: =IF(F43="","",IF(I43="SÍ",F43*'Configuración'!$C$5,0)) -> 0.55 | H43: SÍ | I43: SÍ | J43: =IF(F43="","",IF(H43="SÍ",'Configuración'!$C$6,0)) -> 1.3 | K43: =IF(F43="","",F43-G43-J43) -> 3.15 | L43: =IF(F43="","",K43-E43-IF(N43="",0,N43)) -> 3.14 | M43: =IF(F43="","",IF(K43=0,0,L43/K43)) -> 0.9968254
A44: 40 | B44: 46105 | C44: Cable Pedales | D44: =IFERROR(VLOOKUP(C44,'Catálogo Productos'!$B$3:$E$53,2,0),"") -> Guitarra Electrica | E44: =IFERROR(VLOOKUP(C44,'Catálogo Productos'!$B$3:$E$53,3,0),"") -> 2.3 | F44: =IFERROR(VLOOKUP(C44,'Catálogo Productos'!$B$3:$E$53,4,0),"") -> 14 | G44: =IF(F44="","",IF(I44="SÍ",F44*'Configuración'!$C$5,0)) -> 1.54 | H44: SÍ | I44: SÍ | J44: =IF(F44="","",IF(H44="SÍ",'Configuración'!$C$6,0)) -> 1.3 | K44: =IF(F44="","",F44-G44-J44) -> 11.16 | L44: =IF(F44="","",K44-E44-IF(N44="",0,N44)) -> 8.86 | M44: =IF(F44="","",IF(K44=0,0,L44/K44)) -> 0.79390681
A45: 41 | B45: 46105 | C45: Clavijas Guitarra Clasica Doradas | D45: =IFERROR(VLOOKUP(C45,'Catálogo Productos'!$B$3:$E$53,2,0),"") -> Guitarra Clasica | E45: =IFERROR(VLOOKUP(C45,'Catálogo Productos'!$B$3:$E$53,3,0),"") -> 2.5 | F45: =IFERROR(VLOOKUP(C45,'Catálogo Productos'!$B$3:$E$53,4,0),"") -> 9.99 | G45: =IF(F45="","",IF(I45="SÍ",F45*'Configuración'!$C$5,0)) -> 1.0989 | H45: SÍ | I45: SÍ | J45: =IF(F45="","",IF(H45="SÍ",'Configuración'!$C$6,0)) -> 1.3 | K45: =IF(F45="","",F45-G45-J45) -> 7.5911 | L45: =IF(F45="","",K45-E45-IF(N45="",0,N45)) -> 5.0911 | M45: =IF(F45="","",IF(K45=0,0,L45/K45)) -> 0.67066697
A46: 42 | B46: 46105 | C46: Clavijas Guitarra Clasica Doradas | D46: =IFERROR(VLOOKUP(C46,'Catálogo Productos'!$B$3:$E$53,2,0),"") -> Guitarra Clasica | E46: =IFERROR(VLOOKUP(C46,'Catálogo Productos'!$B$3:$E$53,3,0),"") -> 2.5 | F46: =IFERROR(VLOOKUP(C46,'Catálogo Productos'!$B$3:$E$53,4,0),"") -> 9.99 | G46: =IF(F46="","",IF(I46="SÍ",F46*'Configuración'!$C$5,0)) -> 1.0989 | H46: SÍ | I46: SÍ | J46: =IF(F46="","",IF(H46="SÍ",'Configuración'!$C$6,0)) -> 1.3 | K46: =IF(F46="","",F46-G46-J46) -> 7.5911 | L46: =IF(F46="","",K46-E46-IF(N46="",0,N46)) -> 5.0911 | M46: =IF(F46="","",IF(K46=0,0,L46/K46)) -> 0.67066697
A47: 43 | B47: 46106 | C47: Cuerdas Alice Folk 11-52 | D47: =IFERROR(VLOOKUP(C47,'Catálogo Productos'!$B$3:$E$53,2,0),"") -> Guitarra Acustica | E47: =IFERROR(VLOOKUP(C47,'Catálogo Productos'!$B$3:$E$53,3,0),"") -> 1.21 | F47: =IFERROR(VLOOKUP(C47,'Catálogo Productos'!$B$3:$E$53,4,0),"") -> 5.49 | G47: =IF(F47="","",IF(I47="SÍ",F47*'Configuración'!$C$5,0)) -> 0.6039 | H47: SÍ | I47: SÍ | J47: =IF(F47="","",IF(H47="SÍ",'Configuración'!$C$6,0)) -> 1.3 | K47: =IF(F47="","",F47-G47-J47) -> 3.5861 | L47: =IF(F47="","",K47-E47-IF(N47="",0,N47)) -> 2.3761 | M47: =IF(F47="","",IF(K47=0,0,L47/K47)) -> 0.6625861
A48: 44 | B48: 46106 | C48: Cuerdas Alice Electrica SL | D48: =IFERROR(VLOOKUP(C48,'Catálogo Productos'!$B$3:$E$53,2,0),"") -> Guitarra Electrica | E48: =IFERROR(VLOOKUP(C48,'Catálogo Productos'!$B$3:$E$53,3,0),"") -> 1.21 | F48: =IFERROR(VLOOKUP(C48,'Catálogo Productos'!$B$3:$E$53,4,0),"") -> 5.49 | G48: =IF(F48="","",IF(I48="SÍ",F48*'Configuración'!$C$5,0)) -> 0 | H48: No | I48: NO | J48: =IF(F48="","",IF(H48="SÍ",'Configuración'!$C$6,0)) -> 0 | K48: =IF(F48="","",F48-G48-J48) -> 5.49 | L48: =IF(F48="","",K48-E48-IF(N48="",0,N48)) -> 3.78 | M48: =IF(F48="","",IF(K48=0,0,L48/K48)) -> 0.68852459 | N48: 0.5
A49: 45 | B49: 46106 | C49: Cuerdas Alice Electrica SL | D49: =IFERROR(VLOOKUP(C49,'Catálogo Productos'!$B$3:$E$53,2,0),"") -> Guitarra Electrica | E49: =IFERROR(VLOOKUP(C49,'Catálogo Productos'!$B$3:$E$53,3,0),"") -> 1.21 | F49: =IFERROR(VLOOKUP(C49,'Catálogo Productos'!$B$3:$E$53,4,0),"") -> 5.49 | G49: =IF(F49="","",IF(I49="SÍ",F49*'Configuración'!$C$5,0)) -> 0 | H49: No | I49: NO | J49: =IF(F49="","",IF(H49="SÍ",'Configuración'!$C$6,0)) -> 0 | K49: =IF(F49="","",F49-G49-J49) -> 5.49 | L49: =IF(F49="","",K49-E49-IF(N49="",0,N49)) -> 3.78 | M49: =IF(F49="","",IF(K49=0,0,L49/K49)) -> 0.68852459 | N49: 0.5
A50: 46 | B50: 46106 | C50: Cuerdas Bajo 4C Alice | D50: =IFERROR(VLOOKUP(C50,'Catálogo Productos'!$B$3:$E$53,2,0),"") -> Bajo Electrico | E50: =IFERROR(VLOOKUP(C50,'Catálogo Productos'!$B$3:$E$53,3,0),"") -> 3.03 | F50: =IFERROR(VLOOKUP(C50,'Catálogo Productos'!$B$3:$E$53,4,0),"") -> 12.99 | G50: =IF(F50="","",IF(I50="SÍ",F50*'Configuración'!$C$5,0)) -> 0 | H50: No | I50: NO | J50: =IF(F50="","",IF(H50="SÍ",'Configuración'!$C$6,0)) -> 0 | K50: =IF(F50="","",F50-G50-J50) -> 12.99 | L50: =IF(F50="","",K50-E50-IF(N50="",0,N50)) -> 7.96 | M50: =IF(F50="","",IF(K50=0,0,L50/K50)) -> 0.61277906 | N50: 2
A51: 47 | B51: 46106 | C51: Capotraste | D51: =IFERROR(VLOOKUP(C51,'Catálogo Productos'!$B$3:$E$53,2,0),"") -> Capostraste | E51: =IFERROR(VLOOKUP(C51,'Catálogo Productos'!$B$3:$E$53,3,0),"") -> 0.65 | F51: =IFERROR(VLOOKUP(C51,'Catálogo Productos'!$B$3:$E$53,4,0),"") -> 6.99 | G51: =IF(F51="","",IF(I51="SÍ",F51*'Configuración'!$C$5,0)) -> 0.7689 | H51: SÍ | I51: SÍ | J51: =IF(F51="","",IF(H51="SÍ",'Configuración'!$C$6,0)) -> 1.3 | K51: =IF(F51="","",F51-G51-J51) -> 4.9211 | L51: =IF(F51="","",K51-E51-IF(N51="",0,N51)) -> 4.2711 | M51: =IF(F51="","",IF(K51=0,0,L51/K51)) -> 0.86791571
A52: 48 | B52: 46108 | C52: Cuerdas Alice Electrica L | D52: =IFERROR(VLOOKUP(C52,'Catálogo Productos'!$B$3:$E$53,2,0),"") -> Guitarra Electrica | E52: =IFERROR(VLOOKUP(C52,'Catálogo Productos'!$B$3:$E$53,3,0),"") -> 1.21 | F52: =IFERROR(VLOOKUP(C52,'Catálogo Productos'!$B$3:$E$53,4,0),"") -> 5.49 | G52: =IF(F52="","",IF(I52="SÍ",F52*'Configuración'!$C$5,0)) -> 0.6039 | H52: SÍ | I52: SÍ | J52: =IF(F52="","",IF(H52="SÍ",'Configuración'!$C$6,0)) -> 1.3 | K52: =IF(F52="","",F52-G52-J52) -> 3.5861 | L52: =IF(F52="","",K52-E52-IF(N52="",0,N52)) -> 2.3761 | M52: =IF(F52="","",IF(K52=0,0,L52/K52)) -> 0.6625861
A53: 49 | B53: 46108 | C53: Cuerdas Alice Folk 11-52 | D53: =IFERROR(VLOOKUP(C53,'Catálogo Productos'!$B$3:$E$53,2,0),"") -> Guitarra Acustica | E53: =IFERROR(VLOOKUP(C53,'Catálogo Productos'!$B$3:$E$53,3,0),"") -> 1.21 | F53: =IFERROR(VLOOKUP(C53,'Catálogo Productos'!$B$3:$E$53,4,0),"") -> 5.49 | G53: =IF(F53="","",IF(I53="SÍ",F53*'Configuración'!$C$5,0)) -> 0.6039 | H53: SÍ | I53: SÍ | J53: =IF(F53="","",IF(H53="SÍ",'Configuración'!$C$6,0)) -> 1.3 | K53: =IF(F53="","",F53-G53-J53) -> 3.5861 | L53: =IF(F53="","",K53-E53-IF(N53="",0,N53)) -> 2.3761 | M53: =IF(F53="","",IF(K53=0,0,L53/K53)) -> 0.6625861
A54: 50 | B54: 46110 | C54: Cuerdas Bajo 4C Alice | D54: =IFERROR(VLOOKUP(C54,'Catálogo Productos'!$B$3:$E$53,2,0),"") -> Bajo Electrico | E54: =IFERROR(VLOOKUP(C54,'Catálogo Productos'!$B$3:$E$53,3,0),"") -> 3.03 | F54: =IFERROR(VLOOKUP(C54,'Catálogo Productos'!$B$3:$E$53,4,0),"") -> 12.99 | G54: =IF(F54="","",IF(I54="SÍ",F54*'Configuración'!$C$5,0)) -> 1.4289 | H54: SÍ | I54: SÍ | J54: =IF(F54="","",IF(H54="SÍ",'Configuración'!$C$6,0)) -> 1.3 | K54: =IF(F54="","",F54-G54-J54) -> 10.2611 | L54: =IF(F54="","",K54-E54-IF(N54="",0,N54)) -> 6.2311 | M54: =IF(F54="","",IF(K54=0,0,L54/K54)) -> 0.60725458 | N54: 1
A55: 51 | B55: 46110 | C55: Cuerdas Alice Electrica L | D55: =IFERROR(VLOOKUP(C55,'Catálogo Productos'!$B$3:$E$53,2,0),"") -> Guitarra Electrica | E55: =IFERROR(VLOOKUP(C55,'Catálogo Productos'!$B$3:$E$53,3,0),"") -> 1.21 | F55: =IFERROR(VLOOKUP(C55,'Catálogo Productos'!$B$3:$E$53,4,0),"") -> 5.49 | G55: =IF(F55="","",IF(I55="SÍ",F55*'Configuración'!$C$5,0)) -> 0.6039 | H55: SÍ | I55: SÍ | J55: =IF(F55="","",IF(H55="SÍ",'Configuración'!$C$6,0)) -> 1.3 | K55: =IF(F55="","",F55-G55-J55) -> 3.5861 | L55: =IF(F55="","",K55-E55-IF(N55="",0,N55)) -> 0.8761 | M55: =IF(F55="","",IF(K55=0,0,L55/K55)) -> 0.2443044 | N55: 1.5
A56: 52 | B56: 46111 | C56: Cuerdas Alice Clasica A106 | D56: =IFERROR(VLOOKUP(C56,'Catálogo Productos'!$B$3:$E$53,2,0),"") -> Guitarra Clasica | E56: =IFERROR(VLOOKUP(C56,'Catálogo Productos'!$B$3:$E$53,3,0),"") -> 1.21 | F56: =IFERROR(VLOOKUP(C56,'Catálogo Productos'!$B$3:$E$53,4,0),"") -> 5.49 | G56: =IF(F56="","",IF(I56="SÍ",F56*'Configuración'!$C$5,0)) -> 0.6039 | H56: SÍ | I56: SÍ | J56: =IF(F56="","",IF(H56="SÍ",'Configuración'!$C$6,0)) -> 1.3 | K56: =IF(F56="","",F56-G56-J56) -> 3.5861 | L56: =IF(F56="","",K56-E56-IF(N56="",0,N56)) -> 0.3761 | M56: =IF(F56="","",IF(K56=0,0,L56/K56)) -> 0.10487716 | N56: 2
A57: 53 | B57: 46111 | C57: Cuerdas Alice Clasica A106 | D57: =IFERROR(VLOOKUP(C57,'Catálogo Productos'!$B$3:$E$53,2,0),"") -> Guitarra Clasica | E57: =IFERROR(VLOOKUP(C57,'Catálogo Productos'!$B$3:$E$53,3,0),"") -> 1.21 | F57: =IFERROR(VLOOKUP(C57,'Catálogo Productos'!$B$3:$E$53,4,0),"") -> 5.49 | G57: =IF(F57="","",IF(I57="SÍ",F57*'Configuración'!$C$5,0)) -> 0 | H57: No | I57: NO | J57: =IF(F57="","",IF(H57="SÍ",'Configuración'!$C$6,0)) -> 0 | K57: =IF(F57="","",F57-G57-J57) -> 5.49 | L57: =IF(F57="","",K57-E57-IF(N57="",0,N57)) -> 2.28 | M57: =IF(F57="","",IF(K57=0,0,L57/K57)) -> 0.41530055 | N57: 2
A58: 54 | B58: 46111 | C58: Cuerdas Alice Folk 11-52 | D58: =IFERROR(VLOOKUP(C58,'Catálogo Productos'!$B$3:$E$53,2,0),"") -> Guitarra Acustica | E58: =IFERROR(VLOOKUP(C58,'Catálogo Productos'!$B$3:$E$53,3,0),"") -> 1.21 | F58: =IFERROR(VLOOKUP(C58,'Catálogo Productos'!$B$3:$E$53,4,0),"") -> 5.49 | G58: =IF(F58="","",IF(I58="SÍ",F58*'Configuración'!$C$5,0)) -> 0.6039 | H58: SÍ | I58: SÍ | J58: =IF(F58="","",IF(H58="SÍ",'Configuración'!$C$6,0)) -> 1.3 | K58: =IF(F58="","",F58-G58-J58) -> 3.5861 | L58: =IF(F58="","",K58-E58-IF(N58="",0,N58)) -> 0.8861 | M58: =IF(F58="","",IF(K58=0,0,L58/K58)) -> 0.24709294 | N58: 1.49
A59: 55 | B59: 46111 | C59: Pickguard Negro Guitarra Acustica | D59: =IFERROR(VLOOKUP(C59,'Catálogo Productos'!$B$3:$E$53,2,0),"") -> Guitarra Acustica | E59: =IFERROR(VLOOKUP(C59,'Catálogo Productos'!$B$3:$E$53,3,0),"") -> 0.5 | F59: =IFERROR(VLOOKUP(C59,'Catálogo Productos'!$B$3:$E$53,4,0),"") -> 5 | G59: =IF(F59="","",IF(I59="SÍ",F59*'Configuración'!$C$5,0)) -> 0.55 | H59: SÍ | I59: SÍ | J59: =IF(F59="","",IF(H59="SÍ",'Configuración'!$C$6,0)) -> 1.3 | K59: =IF(F59="","",F59-G59-J59) -> 3.15 | L59: =IF(F59="","",K59-E59-IF(N59="",0,N59)) -> 2.65 | M59: =IF(F59="","",IF(K59=0,0,L59/K59)) -> 0.84126984
A60: 56 | B60: 46112 | C60: Clavijas Guitarra Clasica Doradas | D60: =IFERROR(VLOOKUP(C60,'Catálogo Productos'!$B$3:$E$53,2,0),"") -> Guitarra Clasica | E60: =IFERROR(VLOOKUP(C60,'Catálogo Productos'!$B$3:$E$53,3,0),"") -> 2.5 | F60: =IFERROR(VLOOKUP(C60,'Catálogo Productos'!$B$3:$E$53,4,0),"") -> 9.99 | G60: =IF(F60="","",IF(I60="SÍ",F60*'Configuración'!$C$5,0)) -> 1.0989 | H60: No | I60: SÍ | J60: =IF(F60="","",IF(H60="SÍ",'Configuración'!$C$6,0)) -> 0 | K60: =IF(F60="","",F60-G60-J60) -> 8.8911 | L60: =IF(F60="","",K60-E60-IF(N60="",0,N60)) -> 6.3911 | M60: =IF(F60="","",IF(K60=0,0,L60/K60)) -> 0.71881994
A61: 57 | B61: 46112 | C61: Cuerdas Bajo 4C Alice | D61: =IFERROR(VLOOKUP(C61,'Catálogo Productos'!$B$3:$E$53,2,0),"") -> Bajo Electrico | E61: =IFERROR(VLOOKUP(C61,'Catálogo Productos'!$B$3:$E$53,3,0),"") -> 3.03 | F61: =IFERROR(VLOOKUP(C61,'Catálogo Productos'!$B$3:$E$53,4,0),"") -> 12.99 | G61: =IF(F61="","",IF(I61="SÍ",F61*'Configuración'!$C$5,0)) -> 1.4289 | H61: SÍ | I61: SÍ | J61: =IF(F61="","",IF(H61="SÍ",'Configuración'!$C$6,0)) -> 1.3 | K61: =IF(F61="","",F61-G61-J61) -> 10.2611 | L61: =IF(F61="","",K61-E61-IF(N61="",0,N61)) -> 6.2311 | M61: =IF(F61="","",IF(K61=0,0,L61/K61)) -> 0.60725458 | N61: 1
...

Sheet Marzo 2026 - Resumen
A1: ÁVILA MUSIC - RESUMEN FINANCIERO MENSUAL
A2: ='Configuración'!C20&" "&'Configuración'!C21 -> Abril 2026
A4: RESUMEN DE INGRESOS
B6: Ventas Totales (USD) | C6: ='Marzo 2026 - Ventas'!F64 -> 436.09
B7: (-) Comisiones MercadoLibre | C7: ='Marzo 2026 - Ventas'!G64 -> 44.7293
B8: (-) Costos de Envío | C8: ='Marzo 2026 - Ventas'!J64 -> 70.2
B9: Ingreso Neto (lo que recibes) | C9: ='Marzo 2026 - Ventas'!K64 -> 321.1607
B10: (-) Costo Total de Mercancía | C10: ='Marzo 2026 - Ventas'!E64 -> 76.72
B11: GANANCIA BRUTA | C11: ='Marzo 2026 - Ventas'!L64 -> 230.4507
A13: ANÁLISIS DE GANANCIA
B15: Ingreso Neto (USD) | C15: =C9 -> 321.1607 | E15: Lo que recibes después de comisiones y envíos
B16: Ganancia Bruta (USD) | C16: =C11 -> 230.4507 | E16: Ventas netas menos costo de mercancía
B17: (-) Costo de Mercancía (USD) | C17: =C10 -> 76.72
B18: GANANCIA NETA (USD) | C18: =C15-C10 -> 244.4407
A21: DISTRIBUCIÓN DE GANANCIA REAL
B23: Ganancia Neta del Mes | C23: =C18 -> 244.4407
B24: → Para Reinversión | C24: =IF(C23>0,C23*'Configuración'!$C$14,0) -> 171.10849 | D24: ='Configuración'!$C$14 -> 0.7 | E24: Para comprar más inventario
B25: → Tu Sueldo / Ganancia Personal | C25: =IF(C23>0,C23*'Configuración'!$C$15,0) -> 73.33221 | D25: ='Configuración'!$C$15 -> 0.3 | E25: Disponible para ti o para decisiones
A27: INDICADORES CLAVE (KPIs)
B29: Total de ventas del mes | C29: ='Marzo 2026 - Ventas'!C66 -> 60 | E29: Cantidad de transacciones
B30: Ticket promedio (USD) | C30: =IF(C29>0,C6/C29,0) -> 7.2681667 | E30: Venta promedio por transacción
B31: Ganancia neta promedio por venta | C31: =IF(C29>0,C18/C29,0) -> 4.0740117 | E31: Cuánto ganas en promedio por venta
B32: Margen neto real (%) | C32: =IF(C9=0,0,C18/C9) -> 0.76111648 | E32: % ganancia real sobre ingreso neto
B33: Total pagado a ML (comisiones + envíos) | C33: ='Marzo 2026 - Ventas'!G64+'Marzo 2026 - Ventas'!J64 -> 114.9293 | E33: Lo que le pagas a MercadoLibre
B34: ROI del mes (%) | C34: =IF(C10=0,0,C18/C10) -> 3.1861405 | E34: Retorno sobre inversión en inventario
A36: SEMÁFORO DE SALUD DEL NEGOCIO
B38: ¿Recuperaste la inversión? | C38: =IF(C29=0,"—",IF(C18>0,"✅ SÍ","❌ NO")) -> ✅ SÍ | E38: Ganancia real positiva
B39: ¿El negocio se autosostiene? | C39: =IF(C29=0,"—",IF(C24>0,"✅ SÍ","❌ NO")) -> ✅ SÍ | E39: Hay fondos para reinversión
B40: ¿Genera sueldo para ti? | C40: =IF(C29=0,"—",IF(C25>0,"✅ SÍ","❌ NO")) -> ✅ SÍ | E40: Hay ganancia personal disponible
B41: ¿Superaste 50 ventas? | C41: =IF(C29>=50,"✅ SÍ — ¡Baja tu tarifa de envío!","❌ NO — Aún no") -> ✅ SÍ — ¡Baja tu tarifa de envío! | E41: Meta para reducir costo de envío

Sheet Febrero 2026 - Ventas
A1: ÁVILA MUSIC - REGISTRO DE VENTAS DETALLADO
A2: ='Configuración'!C17&" "&'Configuración'!C18
A4: # | B4: Fecha | C4: Producto | D4: Categoría | E4: Costo USD | F4: Precio Venta USD | G4: Comisión ML | H4: Envío Gratis | I4: Comisión ML | J4: Costo Envío USD | K4: Ingreso Neto USD | L4: Ganancia Bruta USD | M4: Margen % | N4: Descuento USD
A5: 1 | B5: 46056 | C5: Cuerdas Alice Electrica SL | D5: =IFERROR(VLOOKUP(C5,'Catálogo Productos'!$B$3:$E$53,2,0),"") -> Guitarra Electrica | E5: =IFERROR(VLOOKUP(C5,'Catálogo Productos'!$B$3:$E$53,3,0),"") -> 1.21 | F5: =IFERROR(VLOOKUP(C5,'Catálogo Productos'!$B$3:$E$53,4,0),"") -> 5.49 | G5: =IF(F5="","",IF(I5="SÍ",F5*'Configuración'!$C$5,0)) -> 0.6039 | H5: SÍ | I5: SÍ | J5: =IF(F5="","",IF(H5="SÍ",'Configuración'!$C$6,0)) -> 1.3 | K5: =IF(F5="","",F5-G5-J5) -> 3.5861 | L5: =IF(F5="","",K5-E5-IF(N5="",0,N5)) -> 2.3761 | M5: =IF(F5="","",IF(K5=0,0,L5/K5)) -> 0.6625861
A6: 2 | B6: 46056 | C6: Clavijas Guitarra Clasica Doradas | D6: =IFERROR(VLOOKUP(C6,'Catálogo Productos'!$B$3:$E$53,2,0),"") -> Guitarra Clasica | E6: =IFERROR(VLOOKUP(C6,'Catálogo Productos'!$B$3:$E$53,3,0),"") -> 2.5 | F6: =IFERROR(VLOOKUP(C6,'Catálogo Productos'!$B$3:$E$53,4,0),"") -> 9.99 | G6: =IF(F6="","",IF(I6="SÍ",F6*'Configuración'!$C$5,0)) -> 1.0989 | H6: SÍ | I6: SÍ | J6: =IF(F6="","",IF(H6="SÍ",'Configuración'!$C$6,0)) -> 1.3 | K6: =IF(F6="","",F6-G6-J6) -> 7.5911 | L6: =IF(F6="","",K6-E6-IF(N6="",0,N6)) -> 5.0911 | M6: =IF(F6="","",IF(K6=0,0,L6/K6)) -> 0.67066697
A7: 3 | B7: 46057 | C7: Cuerdas Alice Electrica L | D7: =IFERROR(VLOOKUP(C7,'Catálogo Productos'!$B$3:$E$53,2,0),"") -> Guitarra Electrica | E7: =IFERROR(VLOOKUP(C7,'Catálogo Productos'!$B$3:$E$53,3,0),"") -> 1.21 | F7: =IFERROR(VLOOKUP(C7,'Catálogo Productos'!$B$3:$E$53,4,0),"") -> 5.49 | G7: =IF(F7="","",IF(I7="SÍ",F7*'Configuración'!$C$5,0)) -> 0.6039 | H7: SÍ | I7: SÍ | J7: =IF(F7="","",IF(H7="SÍ",'Configuración'!$C$6,0)) -> 1.3 | K7: =IF(F7="","",F7-G7-J7) -> 3.5861 | L7: =IF(F7="","",K7-E7-IF(N7="",0,N7)) -> 2.3761 | M7: =IF(F7="","",IF(K7=0,0,L7/K7)) -> 0.6625861
A8: 4 | B8: 46057 | C8: Cuerdas Alice Electrica SL | D8: =IFERROR(VLOOKUP(C8,'Catálogo Productos'!$B$3:$E$53,2,0),"") -> Guitarra Electrica | E8: =IFERROR(VLOOKUP(C8,'Catálogo Productos'!$B$3:$E$53,3,0),"") -> 1.21 | F8: =IFERROR(VLOOKUP(C8,'Catálogo Productos'!$B$3:$E$53,4,0),"") -> 5.49 | G8: =IF(F8="","",IF(I8="SÍ",F8*'Configuración'!$C$5,0)) -> 0.6039 | H8: SÍ | I8: SÍ | J8: =IF(F8="","",IF(H8="SÍ",'Configuración'!$C$6,0)) -> 1.3 | K8: =IF(F8="","",F8-G8-J8) -> 3.5861 | L8: =IF(F8="","",K8-E8-IF(N8="",0,N8)) -> 2.3761 | M8: =IF(F8="","",IF(K8=0,0,L8/K8)) -> 0.6625861
A9: 5 | B9: 46057 | C9: Cuerdas Alice Electrica L | D9: =IFERROR(VLOOKUP(C9,'Catálogo Productos'!$B$3:$E$53,2,0),"") -> Guitarra Electrica | E9: =IFERROR(VLOOKUP(C9,'Catálogo Productos'!$B$3:$E$53,3,0),"") -> 1.21 | F9: =IFERROR(VLOOKUP(C9,'Catálogo Productos'!$B$3:$E$53,4,0),"") -> 5.49 | G9: =IF(F9="","",IF(I9="SÍ",F9*'Configuración'!$C$5,0)) -> 0.6039 | H9: SÍ | I9: SÍ | J9: =IF(F9="","",IF(H9="SÍ",'Configuración'!$C$6,0)) -> 1.3 | K9: =IF(F9="","",F9-G9-J9) -> 3.5861 | L9: =IF(F9="","",K9-E9-IF(N9="",0,N9)) -> 2.3761 | M9: =IF(F9="","",IF(K9=0,0,L9/K9)) -> 0.6625861
A10: 6 | B10: 46057 | C10: Hombrera Violin 3/4 4/4 | D10: =IFERROR(VLOOKUP(C10,'Catálogo Productos'!$B$3:$E$53,2,0),"") -> Violin | E10: =IFERROR(VLOOKUP(C10,'Catálogo Productos'!$B$3:$E$53,3,0),"") -> 2.69 | F10: =IFERROR(VLOOKUP(C10,'Catálogo Productos'!$B$3:$E$53,4,0),"") -> 11 | G10: =IF(F10="","",IF(I10="SÍ",F10*'Configuración'!$C$5,0)) -> 1.21 | H10: SÍ | I10: SÍ | J10: =IF(F10="","",IF(H10="SÍ",'Configuración'!$C$6,0)) -> 1.3 | K10: =IF(F10="","",F10-G10-J10) -> 8.49 | L10: =IF(F10="","",K10-E10-IF(N10="",0,N10)) -> 5.8 | M10: =IF(F10="","",IF(K10=0,0,L10/K10)) -> 0.68315665
A11: 7 | B11: 46057 | C11: Cuerdas Alice Electrica SL | D11: =IFERROR(VLOOKUP(C11,'Catálogo Productos'!$B$3:$E$53,2,0),"") -> Guitarra Electrica | E11: =IFERROR(VLOOKUP(C11,'Catálogo Productos'!$B$3:$E$53,3,0),"") -> 1.21 | F11: =IFERROR(VLOOKUP(C11,'Catálogo Productos'!$B$3:$E$53,4,0),"") -> 5.49 | G11: =IF(F11="","",IF(I11="SÍ",F11*'Configuración'!$C$5,0)) -> 0.6039 | H11: SÍ | I11: SÍ | J11: =IF(F11="","",IF(H11="SÍ",'Configuración'!$C$6,0)) -> 1.3 | K11: =IF(F11="","",F11-G11-J11) -> 3.5861 | L11: =IF(F11="","",K11-E11-IF(N11="",0,N11)) -> 2.3761 | M11: =IF(F11="","",IF(K11=0,0,L11/K11)) -> 0.6625861
A12: 8 | B12: 46057 | C12: Clavijas Guitarra Clasica Doradas | D12: =IFERROR(VLOOKUP(C12,'Catálogo Productos'!$B$3:$E$53,2,0),"") -> Guitarra Clasica | E12: =IFERROR(VLOOKUP(C12,'Catálogo Productos'!$B$3:$E$53,3,0),"") -> 2.5 | F12: =IFERROR(VLOOKUP(C12,'Catálogo Productos'!$B$3:$E$53,4,0),"") -> 9.99 | G12: =IF(F12="","",IF(I12="SÍ",F12*'Configuración'!$C$5,0)) -> 1.0989 | H12: SÍ | I12: SÍ | J12: =IF(F12="","",IF(H12="SÍ",'Configuración'!$C$6,0)) -> 1.3 | K12: =IF(F12="","",F12-G12-J12) -> 7.5911 | L12: =IF(F12="","",K12-E12-IF(N12="",0,N12)) -> 5.0911 | M12: =IF(F12="","",IF(K12=0,0,L12/K12)) -> 0.67066697
A13: 9 | B13: 46057 | C13: Cuerdas Alice Clasica A106 | D13: =IFERROR(VLOOKUP(C13,'Catálogo Productos'!$B$3:$E$53,2,0),"") -> Guitarra Clasica | E13: =IFERROR(VLOOKUP(C13,'Catálogo Productos'!$B$3:$E$53,3,0),"") -> 1.21 | F13: =IFERROR(VLOOKUP(C13,'Catálogo Productos'!$B$3:$E$53,4,0),"") -> 5.49 | G13: =IF(F13="","",IF(I13="SÍ",F13*'Configuración'!$C$5,0)) -> 0.6039 | H13: SÍ | I13: SÍ | J13: =IF(F13="","",IF(H13="SÍ",'Configuración'!$C$6,0)) -> 1.3 | K13: =IF(F13="","",F13-G13-J13) -> 3.5861 | L13: =IF(F13="","",K13-E13-IF(N13="",0,N13)) -> 2.3761 | M13: =IF(F13="","",IF(K13=0,0,L13/K13)) -> 0.6625861
A14: 10 | B14: 46057 | C14: Correa Guitarra/Bajo | D14: =IFERROR(VLOOKUP(C14,'Catálogo Productos'!$B$3:$E$53,2,0),"") -> Correas | E14: =IFERROR(VLOOKUP(C14,'Catálogo Productos'!$B$3:$E$53,3,0),"") -> 0.2 | F14: =IFERROR(VLOOKUP(C14,'Catálogo Productos'!$B$3:$E$53,4,0),"") -> 5.49 | G14: =IF(F14="","",IF(I14="SÍ",F14*'Configuración'!$C$5,0)) -> 0.6039 | H14: SÍ | I14: SÍ | J14: =IF(F14="","",IF(H14="SÍ",'Configuración'!$C$6,0)) -> 1.3 | K14: =IF(F14="","",F14-G14-J14) -> 3.5861 | L14: =IF(F14="","",K14-E14-IF(N14="",0,N14)) -> 3.3861 | M14: =IF(F14="","",IF(K14=0,0,L14/K14)) -> 0.94422911
A15: 11 | B15: 46057 | C15: Hombrera Violin 3/4 4/4 | D15: =IFERROR(VLOOKUP(C15,'Catálogo Productos'!$B$3:$E$53,2,0),"") -> Violin | E15: =IFERROR(VLOOKUP(C15,'Catálogo Productos'!$B$3:$E$53,3,0),"") -> 2.69 | F15: =IFERROR(VLOOKUP(C15,'Catálogo Productos'!$B$3:$E$53,4,0),"") -> 11 | G15: =IF(F15="","",IF(I15="SÍ",F15*'Configuración'!$C$5,0)) -> 1.21 | H15: SÍ | I15: SÍ | J15: =IF(F15="","",IF(H15="SÍ",'Configuración'!$C$6,0)) -> 1.3 | K15: =IF(F15="","",F15-G15-J15) -> 8.49 | L15: =IF(F15="","",K15-E15-IF(N15="",0,N15)) -> 5.8 | M15: =IF(F15="","",IF(K15=0,0,L15/K15)) -> 0.68315665
A16: 12 | B16: 46057 | C16: Correa Guitarra/Bajo | D16: =IFERROR(VLOOKUP(C16,'Catálogo Productos'!$B$3:$E$53,2,0),"") -> Correas | E16: =IFERROR(VLOOKUP(C16,'Catálogo Productos'!$B$3:$E$53,3,0),"") -> 0.2 | F16: =IFERROR(VLOOKUP(C16,'Catálogo Productos'!$B$3:$E$53,4,0),"") -> 5.49 | G16: =IF(F16="","",IF(I16="SÍ",F16*'Configuración'!$C$5,0)) -> 0.6039 | H16: SÍ | I16: SÍ | J16: =IF(F16="","",IF(H16="SÍ",'Configuración'!$C$6,0)) -> 1.3 | K16: =IF(F16="","",F16-G16-J16) -> 3.5861 | L16: =IF(F16="","",K16-E16-IF(N16="",0,N16)) -> 3.3861 | M16: =IF(F16="","",IF(K16=0,0,L16/K16)) -> 0.94422911
